<?xml version="1.0" ?>
<robot name="kuka_lbr_iiwa_14_r820" xmlns:xacro="http://wiki.ros.org/xacro">
  <xacro:include filename="$(find iiwa_description)/urdf/materials.xacro"/>
  <!-- Import all Gazebo-customization elements, including Gazebo colors -->
  <xacro:include filename="$(find iiwa_description)/urdf/iiwa.gazebo.xacro" />
  <!-- Import Transmissions -->
  <xacro:include filename="$(find iiwa_description)/urdf/iiwa.transmission.xacro" />
  <!-- Include Utilities -->
  <xacro:include filename="$(find iiwa_description)/urdf/utilities.xacro" />
  
  <!-- some constants -->
  <xacro:property name="safety_controller_k_pos" value="100" />
  <xacro:property name="safety_controller_k_vel" value="2" /> 
  <xacro:property name="joint_damping" value="0.5" />
  <xacro:property name="max_effort" value="300"/>
  <xacro:property name="max_velocity" value="10"/>

    <!-- world_frame -->
  <link name="world_frame"/>
<!-- world_base_joint -->
  <joint name="world_base_joint" type="fixed">		
    <origin rpy="0 0 0" xyz="0 0 0"/>	
<!-- original is rpy="0 0 0" xyz="0 0 0", the offset btw kuka and SP is rpy="PI PI 0" xyz="0.415 0 0.028" -->
    <parent link="world_frame"/>
    <child link="iiwa14_link_0"/>
  </joint>
    
    <link name="iiwa14_link_0">
      <inertial>
        <origin xyz="-0.1 0 0.07" rpy="0 0 0"/>
        <mass value="5"/>
        <inertia ixx="0.05"  ixy="0"  ixz="0" iyy="0.06" iyz="0" izz="0.03" />
      </inertial>
      
      <visual>
        <origin xyz="0 0 0" rpy="0 0 0"/>
        <geometry>
          <mesh filename="package://iiwa_description/meshes/iiwa14/visual/link_0.stl"/>
        </geometry>
        <material name="Grey"/>
      </visual>
      
      <collision>
        <origin xyz="0 0 0" rpy="0 0 0"/>
        <geometry>
          <mesh filename="package://iiwa_description/meshes/iiwa14/collision/link_0.stl"/>
        </geometry>
        <material name="Grey"/>
      </collision>
      
      <self_collision_checking>
        <origin xyz="0 0 0" rpy="0 0 0"/>
        <geometry>
          <capsule radius="0.15" length="0.25"/>
        </geometry>
      </self_collision_checking>
      
    </link>
    
    <!-- joint between link_0 and link_1 -->
    <joint name="iiwa14_joint_1" type="revolute">
      <parent link="iiwa14_link_0"/>
      <child link="iiwa14_link_1"/>
      <origin xyz="0 0 0.1575" rpy="0 0 0"/>
      <axis xyz="0 0 1"/>
      <limit lower="${-170 * PI / 180}" upper="${170 * PI / 180}"
             effort="${max_effort}" velocity="${max_velocity}" />
      <safety_controller soft_lower_limit="${-168 * PI / 180}"
                         soft_upper_limit="${168 * PI / 180}"
                         k_position="${safety_controller_k_pos}"
                         k_velocity="${safety_controller_k_vel}"/> 
      <dynamics damping="${joint_damping}"/>
    </joint>
    
    <link name="iiwa14_link_1">
      <inertial>
        <origin xyz="0 -0.03 0.12" rpy="0 0 0"/>
        <mass value="4"/>
        <inertia ixx="0.1"  ixy="0"  ixz="0" iyy="0.09" iyz="0" izz="0.02" />
      </inertial>
      
      <visual>
        <origin xyz="0 0 0" rpy="0 0 0"/>
        <geometry>
          <mesh filename="package://iiwa_description/meshes/iiwa14/visual/link_1.stl"/>
        </geometry>
        <material name="Orange"/>
      </visual>
      
      <collision>
        <origin xyz="0 0 0" rpy="0 0 0"/>
        <geometry>
          <mesh filename="package://iiwa_description/meshes/iiwa14/collision/link_1.stl"/>
        </geometry>
        <material name="Orange"/>
      </collision>
    </link>
    
    <!-- joint between link_1 and link_2 -->
    <joint name="iiwa14_joint_2" type="revolute">
      <parent link="iiwa14_link_1"/>
      <child link="iiwa14_link_2"/>
      <origin xyz="0 0 0.2025" rpy="${PI / 2}   0 ${PI}"/>
      <axis xyz="0 0 1"/>
      <limit lower="${-120 * PI / 180}" upper="${120 * PI / 180}"
             effort="${max_effort}" velocity="${max_velocity}" />
      <safety_controller soft_lower_limit="${-118 * PI / 180}"
                         soft_upper_limit="${118 * PI / 180}"
                         k_position="${safety_controller_k_pos}"
                         k_velocity="${safety_controller_k_vel}"/> 
      <dynamics damping="${joint_damping}"/>
    </joint>
    
    <link name="iiwa14_link_2">
      <inertial>
        <origin xyz="0.0003 0.059 0.042" rpy="0 0 0"/>
        <mass value="4"/>
        <inertia ixx="0.05"  ixy="0"  ixz="0" iyy="0.018" iyz="0" izz="0.044" />
      </inertial>
      
      <visual>
        <origin xyz="0 0 0" rpy="0 0 0"/>
        <geometry>
          <mesh filename="package://iiwa_description/meshes/iiwa14/visual/link_2.stl"/>
        </geometry>
        <material name="Orange"/>
      </visual>
      
      <collision>
        <origin xyz="0 0 0" rpy="0 0 0"/>
        <geometry>
          <mesh filename="package://iiwa_description/meshes/iiwa14/collision/link_2.stl"/>
        </geometry>
        <material name="Orange"/>
      </collision>
    </link>
    
    <!-- joint between link_2 and link_3 -->
    <joint name="iiwa14_joint_3" type="revolute">
      <parent link="iiwa14_link_2"/>
      <child link="iiwa14_link_3"/>
      <origin xyz="0 0.2045 0" rpy="${PI / 2} 0 ${PI}"/>
      <axis xyz="0 0 1"/>
      <limit lower="${-170 * PI / 180}" upper="${170 * PI / 180}"
             effort="${max_effort}" velocity="${max_velocity}" />
      <safety_controller soft_lower_limit="${-168 * PI / 180}"
                         soft_upper_limit="${168 * PI / 180}"
                         k_position="${safety_controller_k_pos}"
                         k_velocity="${safety_controller_k_vel}"/> 
      <dynamics damping="${joint_damping}"/>
    </joint>
    
    <link name="iiwa14_link_3">
      <inertial>
        <origin xyz="0 0.03 0.13" rpy="0 0 0"/>
        <mass value="3"/>
        <inertia ixx="0.08"  ixy="0"  ixz="0" iyy="0.075" iyz="0" izz="0.01" />
      </inertial>
      
      <visual>
        <origin xyz="0 0 0" rpy="0 0 0"/>
        <geometry>
          <mesh filename="package://iiwa_description/meshes/iiwa14/visual/link_3.stl"/>
        </geometry>
        <material name="Orange"/>
      </visual>
      
      <collision>
        <origin xyz="0 0 0" rpy="0 0 0"/>
        <geometry>
          <mesh filename="package://iiwa_description/meshes/iiwa14/collision/link_3.stl"/>
        </geometry>
        <material name="Orange"/>
      </collision>
    </link>
    
    <!-- joint between link_3 and link_4 -->
    <joint name="iiwa14_joint_4" type="revolute">
      <parent link="iiwa14_link_3"/>
      <child link="iiwa14_link_4"/>
      <origin xyz="0 0 0.2155" rpy="${PI / 2} ${-PI / 2} 0"/>
      <axis xyz="0 0 1"/>
      <limit lower="${-120 * PI / 180}" upper="${120 * PI / 180}"
             effort="${max_effort}" velocity="${max_velocity}" />
      <safety_controller soft_lower_limit="${-118 * PI / 180}"
                         soft_upper_limit="${118 * PI / 180}"
                         k_position="${safety_controller_k_pos}"
                         k_velocity="${safety_controller_k_vel}"/> 
      <dynamics damping="${joint_damping}"/>
    </joint>
    
    <link name="iiwa14_link_4">
      <inertial>
        <origin xyz="0 0.067 0.034" rpy="0 0 0"/>
        <mass value="2.7"/>
        <inertia ixx="0.03"  ixy="0"  ixz="0" iyy="0.01" iyz="0" izz="0.029" />
      </inertial>
      
      <visual>
        <origin xyz="0 0 0" rpy="0 0 0"/>
        <geometry>
          <mesh filename="package://iiwa_description/meshes/iiwa14/visual/link_4.stl"/>
        </geometry>
        <material name="Orange"/>
      </visual>
      
      <collision>
        <origin xyz="0 0 0" rpy="0 0 0"/>
        <geometry>
          <mesh filename="package://iiwa_description/meshes/iiwa14/collision/link_4.stl"/>
        </geometry>
        <material name="Orange"/>
      </collision>
    </link>
    
    <!-- joint between link_4 and link_5 -->
    <joint name="iiwa14_joint_5" type="revolute">
      <parent link="iiwa14_link_4"/>
      <child link="iiwa14_link_5"/>
      <origin xyz="0 0.1845 0" rpy="${-PI / 2} ${PI} 0"/>
      <axis xyz="0 0 1"/>
      <limit lower="${-170 * PI / 180}" upper="${170 * PI / 180}"
             effort="${max_effort}" velocity="${max_velocity}" />
      <safety_controller soft_lower_limit="${-168 * PI / 180}"
                         soft_upper_limit="${168 * PI / 180}"
                         k_position="${safety_controller_k_pos}"
                         k_velocity="${safety_controller_k_vel}"/> 
      <dynamics damping="${joint_damping}"/>
    </joint>
    
    <link name="iiwa14_link_5">
      <inertial>
        <origin xyz="0.0001 0.021 0.076" rpy="0 0 0"/>
        <mass value="1.7"/>
        <inertia ixx="0.02"  ixy="0"  ixz="0" iyy="0.018" iyz="0" izz="0.005" />
      </inertial>
      
      <visual>
        <origin xyz="0 0 0" rpy="0 0 0"/>
        <geometry>
          <mesh filename="package://iiwa_description/meshes/iiwa14/visual/link_5.stl"/>
        </geometry>
        <material name="Orange"/>
      </visual>
      
      <collision>
        <origin xyz="0 0 0" rpy="0 0 0"/>
        <geometry>
          <mesh filename="package://iiwa_description/meshes/iiwa14/collision/link_5.stl"/>
        </geometry>
        <material name="Orange"/>
      </collision>
    </link>
    
    <!-- joint between link_5 and link_6 -->
    <joint name="iiwa14_joint_6" type="revolute">
      <parent link="iiwa14_link_5"/>
      <child link="iiwa14_link_6"/>
      <origin xyz="0 0 0.2155" rpy="${PI / 2} 0 0"/>
      <axis xyz="0 0 1"/>
      <limit lower="${-120 * PI / 180}" upper="${120 * PI / 180}"
             effort="${max_effort}" velocity="${max_velocity}" />
      <safety_controller soft_lower_limit="${-118 * PI / 180}"
                         soft_upper_limit="${118 * PI / 180}"
                         k_position="${safety_controller_k_pos}"
                         k_velocity="${safety_controller_k_vel}"/> 
      <dynamics damping="${joint_damping}"/>
    </joint>
    
    <link name="iiwa14_link_6">
      <inertial>
        <origin xyz="0 0.0006 0.0004" rpy="0 0 0"/>
        <mass value="1.8"/>
        <inertia ixx="0.005"  ixy="0"  ixz="0" iyy="0.0036" iyz="0" izz="0.0047" />
      </inertial>
      
      <visual>
        <origin xyz="0 0 0" rpy="0 0 0"/>
        <geometry>
          <mesh filename="package://iiwa_description/meshes/iiwa14/visual/link_6.stl"/>
        </geometry>
        <material name="Orange"/>
      </visual>
      
      <collision>
        <origin xyz="0 0 0" rpy="0 0 0"/>
        <geometry>
          <mesh filename="package://iiwa_description/meshes/iiwa14/collision/link_6.stl"/>
        </geometry>
        <material name="Orange"/>
      </collision>
    </link>
    
    <!-- joint between link_6 and link_7 -->
    <joint name="iiwa14_joint_7" type="revolute">
      <parent link="iiwa14_link_6"/>
      <child link="iiwa14_link_7"/>
      <origin xyz="0 0.081 0" rpy="${- PI / 2} ${PI} 0"/>
      <axis xyz="0 0 1"/>
      <limit lower="${-175 * PI / 180}" upper="${175 * PI / 180}"
             effort="${max_effort}" velocity="${max_velocity}" />
      <safety_controller soft_lower_limit="${-173 * PI / 180}"
                         soft_upper_limit="${173 * PI / 180}"
                         k_position="${safety_controller_k_pos}"
                         k_velocity="${safety_controller_k_vel}"/> 
      <dynamics damping="${joint_damping}"/>
    </joint>
    
    <link name="iiwa14_link_7">
      <inertial>
        <origin xyz="0 0 0.02" rpy="0 0 0"/>
        <mass value="0.3"/>
        <inertia ixx="0.001"  ixy="0"  ixz="0" iyy="0.001" iyz="0" izz="0.001" />
      </inertial>
      
      <visual>
        <origin xyz="0 0 0" rpy="0 0 0"/>
        <geometry>
          <mesh filename="package://iiwa_description/meshes/iiwa14/visual/link_7.stl"/>
        </geometry>
        <material name="Grey"/>
      </visual>
      
      <collision>
        <origin xyz="0 0 0" rpy="0 0 0"/>
        <geometry>
          <mesh filename="package://iiwa_description/meshes/iiwa14/collision/link_7.stl"/>
        </geometry>
        <material name="Grey"/>
      </collision>
    </link>
    
    <joint name="iiwa14_joint_ee" type="fixed">
      <parent link="iiwa14_link_7"/>
      <child link="iiwa14_link_ee"/>
      <origin xyz="0 0 0.045" rpy="0 0 0"/>
    </joint>
    
    <link name="iiwa14_link_ee">
      <inertial>  <!-- Source: https://bit.ly/387NqqL -->
         <origin xyz="0 0 0" rpy="0 0 0"/> 
         <mass value="0.001"/> 
      <inertia ixx="1.0" ixy="0.0" ixz="0.0" iyy="1.0" iyz="0.0" izz="1.0"/> 
      </inertial>
    </link>

  <!-- Included by HT 
    <joint name="ft_joint_ee" type="fixed">
      <parent link="iiwa14_link_ee"/>
      <child link="ft_sensor_link"/>
      <origin xyz="0 0 0.0" rpy="0 0 0"/>
    </joint>
 -->
    <!-- Included by HT  -->
    <joint name="ft_joint_ee" type="revolute">
      <parent link="iiwa14_link_ee"/>
      <child link="ft_sensor_link"/>
      <origin xyz="0 0 0.0" rpy="0 0 0"/>
      <limit velocity="6.5" effort="1000" lower="0" upper="0" /> Source: https://bit.ly/2LsS1Ky -->
    </joint>

    <!-- Include tool to the EE  name="visual_cylinder" -->
    <link name="ft_sensor_link"> 
      <inertial>
        <origin xyz="0 0 0.02" rpy="0 0 0"/>
        <mass value="0.01"/>
        <inertia ixx="0.001"  ixy="0"  ixz="0" iyy="0.001" iyz="0" izz="0.001" />
      </inertial>  
       <visual >
         <origin xyz="0.0 0 0.0 " rpy="0 0 0"/>
         <geometry>
           <cylinder radius="0.01" length="0.07"/>
         </geometry>
       </visual>
       <collision>
         <origin xyz="0 0 0" rpy="0 0 0"/>
           <geometry>
             <cylinder radius="0.01" length="0.07"/>
           </geometry>
           <material name="Grey"/>
       </collision>    
    </link>
<!-- contact_point_joint -->
  <joint name="contact_point_joint" type="fixed">
<!-- 0.155/0.17 for metal tool with boardmarker, 0.205/0.21 for polymer tool with sponge -->
    <origin rpy="0 0 0" xyz="0 0 0.21"/>
    <parent link="ft_sensor_link"/>
    <child link="contact_point"/>
  </joint>
<!-- contact_point -->
  <link name="contact_point">
    <visual>
      <origin rpy="0 0 0" xyz="0 0 0"/>
      <geometry>
        <sphere radius="0.0375"/>
      </geometry>
      <material name="Grey"/>
    </visual>
  </link>

    <!--Extensions -->
<!--	
    <xacro:iiwa_gazebo robot_name="iiwa14" />
    <xacro:iiwa_transmission hardware_interface="${hardware_interface}"/>
-->  
  </xacro:macro>

  
</robot>
